Traceback (most recent call last):
  File "/home/dan/miniconda3/envs/jbook/lib/python3.10/site-packages/jupyter_cache/executors/utils.py", line 51, in single_nb_execution
    executenb(
  File "/home/dan/miniconda3/envs/jbook/lib/python3.10/site-packages/nbclient/client.py", line 1204, in execute
    return NotebookClient(nb=nb, resources=resources, km=km, **kwargs).execute()
  File "/home/dan/miniconda3/envs/jbook/lib/python3.10/site-packages/nbclient/util.py", line 84, in wrapped
    return just_run(coro(*args, **kwargs))
  File "/home/dan/miniconda3/envs/jbook/lib/python3.10/site-packages/nbclient/util.py", line 62, in just_run
    return loop.run_until_complete(coro)
  File "/home/dan/miniconda3/envs/jbook/lib/python3.10/asyncio/base_events.py", line 646, in run_until_complete
    return future.result()
  File "/home/dan/miniconda3/envs/jbook/lib/python3.10/site-packages/nbclient/client.py", line 663, in async_execute
    await self.async_execute_cell(
  File "/home/dan/miniconda3/envs/jbook/lib/python3.10/site-packages/nbclient/client.py", line 965, in async_execute_cell
    await self._check_raise_for_error(cell, cell_index, exec_reply)
  File "/home/dan/miniconda3/envs/jbook/lib/python3.10/site-packages/nbclient/client.py", line 862, in _check_raise_for_error
    raise CellExecutionError.from_cell_and_msg(cell, exec_reply_content)
nbclient.exceptions.CellExecutionError: An error occurred while executing the following cell:
------------------
nta_311 = rs_to_gdf(_nta_311)
fig, ax = plt.subplots()
nta_311.plot(column='num_complaints', ax=ax, legend=True)
ax.set_title('NYC Flooding 311 Complaints 2010-2022')
------------------

[0;31m---------------------------------------------------------------------------[0m
[0;31mNameError[0m                                 Traceback (most recent call last)
Cell [0;32mIn [25], line 1[0m
[0;32m----> 1[0m nta_311 [38;5;241m=[39m rs_to_gdf([43m_nta_311[49m)
[1;32m      2[0m fig, ax [38;5;241m=[39m plt[38;5;241m.[39msubplots()
[1;32m      3[0m nta_311[38;5;241m.[39mplot(column[38;5;241m=[39m[38;5;124m'[39m[38;5;124mnum_complaints[39m[38;5;124m'[39m, ax[38;5;241m=[39max, legend[38;5;241m=[39m[38;5;28;01mTrue[39;00m)

[0;31mNameError[0m: name '_nta_311' is not defined
NameError: name '_nta_311' is not defined

